
<?xml version="1.0" ?>
<sdf version="1.8">
  <model name="firescout_bot">
    <static>false</static>

    <link name="chassis">
      <pose>0 0 0.10 0 0 0</pose>
      <inertial>
        <mass>3.0</mass>
        <inertia>
          <ixx>0.08</ixx>
          <ixy>0.0</ixy>
          <ixz>0.0</ixz>
          <iyy>0.08</iyy>
          <iyz>0.0</iyz>
          <izz>0.10</izz>
        </inertia>
      </inertial>

      <visual name="chassis_visual">
        <geometry>
          <box>
            <size>0.45 0.32 0.14</size>
          </box>
        </geometry>
        <material>
          <ambient>0.16 0.45 0.78 1</ambient>
          <diffuse>0.16 0.45 0.78 1</diffuse>
          <specular>0.05 0.05 0.05 1</specular>
        </material>
      </visual>

      <collision name="chassis_collision">
        <geometry>
          <box>
            <size>0.45 0.32 0.14</size>
          </box>
        </geometry>
      </collision>
    </link>

    <link name="left_wheel">
      <pose>0.0 0.18 0.07 0 0 0</pose>
      <inertial>
        <mass>0.6</mass>
        <inertia>
          <ixx>0.004</ixx>
          <ixy>0.0</ixy>
          <ixz>0.0</ixz>
          <iyy>0.004</iyy>
          <iyz>0.0</iyz>
          <izz>0.004</izz>
        </inertia>
      </inertial>
      <visual name="left_wheel_visual">
        <geometry>
          <sphere>
            <radius>0.08</radius>
          </sphere>
        </geometry>
        <material>
          <ambient>0.08 0.08 0.08 1</ambient>
          <diffuse>0.08 0.08 0.08 1</diffuse>
        </material>
      </visual>
      <collision name="left_wheel_collision">
        <geometry>
          <sphere>
            <radius>0.08</radius>
          </sphere>
        </geometry>
      </collision>
    </link>

    <link name="right_wheel">
      <pose>0.0 -0.18 0.07 0 0 0</pose>
      <inertial>
        <mass>0.6</mass>
        <inertia>
          <ixx>0.004</ixx>
          <ixy>0.0</ixy>
          <ixz>0.0</ixz>
          <iyy>0.004</iyy>
          <iyz>0.0</iyz>
          <izz>0.004</izz>
        </inertia>
      </inertial>
      <visual name="right_wheel_visual">
        <geometry>
          <sphere>
            <radius>0.08</radius>
          </sphere>
        </geometry>
        <material>
          <ambient>0.08 0.08 0.08 1</ambient>
          <diffuse>0.08 0.08 0.08 1</diffuse>
        </material>
      </visual>
      <collision name="right_wheel_collision">
        <geometry>
          <sphere>
            <radius>0.08</radius>
          </sphere>
        </geometry>
      </collision>
    </link>

    <link name="caster">
      <pose>-0.16 0.0 0.04 0 0 0</pose>
      <inertial>
        <mass>0.2</mass>
        <inertia>
          <ixx>0.001</ixx>
          <ixy>0.0</ixy>
          <ixz>0.0</ixz>
          <iyy>0.001</iyy>
          <iyz>0.0</iyz>
          <izz>0.001</izz>
        </inertia>
      </inertial>
      <visual name="caster_visual">
        <geometry>
          <sphere>
            <radius>0.04</radius>
          </sphere>
        </geometry>
      </visual>
      <collision name="caster_collision">
        <geometry>
          <sphere>
            <radius>0.04</radius>
          </sphere>
        </geometry>
      </collision>
    </link>

    <joint name="left_wheel_joint" type="revolute">
      <parent>chassis</parent>
      <child>left_wheel</child>
      <axis>
        <xyz>0 1 0</xyz>
        <limit>
          <lower>-1.79769e+308</lower>
          <upper>1.79769e+308</upper>
        </limit>
      </axis>
    </joint>

    <joint name="right_wheel_joint" type="revolute">
      <parent>chassis</parent>
      <child>right_wheel</child>
      <axis>
        <xyz>0 1 0</xyz>
        <limit>
          <lower>-1.79769e+308</lower>
          <upper>1.79769e+308</upper>
        </limit>
      </axis>
    </joint>

    <joint name="caster_joint" type="ball">
      <parent>chassis</parent>
      <child>caster</child>
    </joint>

    <plugin
      filename="ignition-gazebo-diff-drive-system"
      name="ignition::gazebo::systems::DiffDrive">
      <left_joint>left_wheel_joint</left_joint>
      <right_joint>right_wheel_joint</right_joint>
      <wheel_separation>0.36</wheel_separation>
      <wheel_radius>0.08</wheel_radius>
      <odom_publish_frequency>10</odom_publish_frequency>
      <max_linear_velocity>0.6</max_linear_velocity>
      <min_linear_velocity>-0.6</min_linear_velocity>
      <max_angular_velocity>1.5</max_angular_velocity>
      <min_angular_velocity>-1.5</min_angular_velocity>
      <max_linear_acceleration>1.0</max_linear_acceleration>
      <max_angular_acceleration>2.0</max_angular_acceleration>
    </plugin>
  </model>
</sdf>